python /cmlscratch/pan/RLHF_Poisoning/jailbreak_rlhf/train_reward.py --model="opt_350m" --epoch=15 --sft_epoch=5 --dataset="hh_poisoned" --per=0.05
------
Traceback (most recent call last):
  File "/cmlscratch/pan/conda/lib/python3.11/site-packages/transformers/utils/hub.py", line 389, in cached_file
    resolved_file = hf_hub_download(
                    ^^^^^^^^^^^^^^^^
  File "/cmlscratch/pan/conda/lib/python3.11/site-packages/huggingface_hub/utils/_validators.py", line 110, in _inner_fn
    validate_repo_id(arg_value)
  File "/cmlscratch/pan/conda/lib/python3.11/site-packages/huggingface_hub/utils/_validators.py", line 158, in validate_repo_id
    raise HFValidationError(
huggingface_hub.utils._validators.HFValidationError: Repo id must be in the form 'repo_name' or 'namespace/repo_name': '/cmlscratch/pan/RLHF_Poisoning/models/opt_350m_5_hh_poisoned_0.05'. Use `repo_type` argument if needed.

The above exception was the direct cause of the following exception:

Traceback (most recent call last):
  File "/cmlscratch/pan/RLHF_Poisoning/jailbreak_rlhf/train_reward.py", line 35, in <module>
    model = AutoModelForSequenceClassification.from_pretrained("/cmlscratch/pan/RLHF_Poisoning/models/opt_350m_" + str(sft_epochs) + "_" + str(args.dataset) + "_" + str(args.per) )
            ^^^^^^^^^^^^^^^^^^^^^^^^^^^^^^^^^^^^^^^^^^^^^^^^^^^^^^^^^^^^^^^^^^^^^^^^^^^^^^^^^^^^^^^^^^^^^^^^^^^^^^^^^^^^^^^^^^^^^^^^^^^^^^^^^^^^^^^^^^^^^^^^^^^^^^^^^^^^^^^^^^^^^^^^
  File "/cmlscratch/pan/conda/lib/python3.11/site-packages/transformers/models/auto/auto_factory.py", line 488, in from_pretrained
    resolved_config_file = cached_file(
                           ^^^^^^^^^^^^
  File "/cmlscratch/pan/conda/lib/python3.11/site-packages/transformers/utils/hub.py", line 454, in cached_file
    raise EnvironmentError(
OSError: Incorrect path_or_model_id: '/cmlscratch/pan/RLHF_Poisoning/models/opt_350m_5_hh_poisoned_0.05'. Please provide either the path to a local folder or the repo_id of a model on the Hub.
END of SLURM commands
